<?xml version="1.0" encoding="utf-8"?>
<!-- This URDF was automatically created by SolidWorks to URDF Exporter! Originally created by Stephen Brawner (brawner@gmail.com) 
     Commit Version: 1.6.0-4-g7f85cfe  Build Version: 1.6.7995.38578
     For more information, please see http://wiki.ros.org/sw_urdf_exporter -->
<robot
  name="robot_description5">
  <link
    name="base_link">
    <inertial>
      <origin
        xyz="0.018890542943976 -0.000142023972111771 0.39945800630367"
        rpy="0 0 0" />
      <mass
        value="0.2370067602234" />
      <inertia
        ixx="3.41733986861111"
        ixy="-0.000493085481469591"
        ixz="-0.0230664579940298"
        iyy="3.19314565985515"
        iyz="-0.000545981635449765"
        izz="1.85246829458927" />
    </inertial>
    <visual>
      <origin
        xyz="0 0 0"
        rpy="0 0 0" />
      <geometry>
        <mesh
          filename="package://robot_description5/meshes/base_link.STL" />
      </geometry>
      <material
        name="">
        <color
          rgba="1 1 1 1" />
      </material>
    </visual>
    <collision>
      <origin
        xyz="0 0 0"
        rpy="0 0 0" />
      <geometry>
        <mesh
          filename="package://robot_description5/meshes/base_link.STL" />
      </geometry>
    </collision>
  </link>
  <link
    name="Wheel_lb_Link">
    <inertial>
      <origin
        xyz="-8.32667268468867E-17 0.0022127176247605 0"
        rpy="0 0 0" />
      <mass
        value="0.0467807531290496" />
      <inertia
        ixx="0.0181551617250659"
        ixy="6.50521303491303E-19"
        ixz="-8.13638808278216E-22"
        iyy="0.0267269473605868"
        iyz="2.59069752656668E-19"
        izz="0.0181551617250659" />
    </inertial>
    <visual>
      <origin
        xyz="0 0 0"
        rpy="0 0 0" />
      <geometry>
        <mesh
          filename="package://robot_description5/meshes/Wheel_lb_Link.STL" />
      </geometry>
      <material
        name="">
        <color
          rgba="0.752941176470588 0.752941176470588 0.752941176470588 1" />
      </material>
    </visual>
    <collision>
      <origin
        xyz="0 0 0"
        rpy="0 0 0" />
      <geometry>
        <mesh
          filename="package://robot_description5/meshes/Wheel_lb_Link.STL" />
      </geometry>
    </collision>
  </link>
  <joint
    name="Wheel_lb_Joint"
    type="continuous">
    <origin
      xyz="-0.17 0.31 0.0450000000000002"
      rpy="0 0 0" />
    <parent
      link="base_link" />
    <child
      link="Wheel_lb_Link" />
    <axis
      xyz="0 -1 0" />
  </joint>
  <link
    name="Wheel_lf_Link">
    <inertial>
      <origin
        xyz="0.1125 0.00221271762476039 1.11022302462516E-16"
        rpy="0 0 0" />
      <mass
        value="0.0467807531290496" />
      <inertia
        ixx="0.0181551617250659"
        ixy="1.95156391047391E-18"
        ixz="-8.1363880827783E-22"
        iyy="0.0267269473605868"
        iyz="2.5906975265667E-19"
        izz="0.0181551617250659" />
    </inertial>
    <visual>
      <origin
        xyz="0 0 0"
        rpy="0 0 0" />
      <geometry>
        <mesh
          filename="package://robot_description5/meshes/Wheel_lf_Link.STL" />
      </geometry>
      <material
        name="">
        <color
          rgba="0.752941176470588 0.752941176470588 0.752941176470588 1" />
      </material>
    </visual>
    <collision>
      <origin
        xyz="0 0 0"
        rpy="0 0 0" />
      <geometry>
        <mesh
          filename="package://robot_description5/meshes/Wheel_lf_Link.STL" />
      </geometry>
    </collision>
  </link>
  <joint
    name="Wheel_lf_Joint"
    type="continuous">
    <origin
      xyz="0.0575 0.31 0.045"
      rpy="0 0 0" />
    <parent
      link="base_link" />
    <child
      link="Wheel_lf_Link" />
    <axis
      xyz="0 -1 0" />
  </joint>
  <link
    name="Wheel_rb_Link">
    <inertial>
      <origin
        xyz="0 -0.00221271762476044 1.11022302462516E-16"
        rpy="0 0 0" />
      <mass
        value="0.0467807531290496" />
      <inertia
        ixx="0.0181551617250659"
        ixy="-2.16840434497101E-18"
        ixz="-3.76901499006041E-19"
        iyy="0.0267269473605868"
        iyz="3.09373401857912E-20"
        izz="0.0181551617250659" />
    </inertial>
    <visual>
      <origin
        xyz="0 0 0"
        rpy="0 0 0" />
      <geometry>
        <mesh
          filename="package://robot_description5/meshes/Wheel_rb_Link.STL" />
      </geometry>
      <material
        name="">
        <color
          rgba="0.752941176470588 0.752941176470588 0.752941176470588 1" />
      </material>
    </visual>
    <collision>
      <origin
        xyz="0 0 0"
        rpy="0 0 0" />
      <geometry>
        <mesh
          filename="package://robot_description5/meshes/Wheel_rb_Link.STL" />
      </geometry>
    </collision>
  </link>
  <joint
    name="Wheel_rb_Joint"
    type="continuous">
    <origin
      xyz="-0.17 -0.31 0.0449999999999999"
      rpy="0 0 0" />
    <parent
      link="base_link" />
    <child
      link="Wheel_rb_Link" />
    <axis
      xyz="0 -1 0" />
  </joint>
  <link
    name="Wheel_rf_link">
    <inertial>
      <origin
        xyz="2.77555756156289E-17 -0.00221271762476044 -1.11022302462516E-16"
        rpy="0 0 0" />
      <mass
        value="0.0467807531290496" />
      <inertia
        ixx="0.0181551617250659"
        ixy="6.50521303491303E-19"
        ixz="-3.97440697321938E-18"
        iyy="0.0267269473605868"
        iyz="-4.69696288073333E-19"
        izz="0.0181551617250659" />
    </inertial>
    <visual>
      <origin
        xyz="0 0 0"
        rpy="0 0 0" />
      <geometry>
        <mesh
          filename="package://robot_description5/meshes/Wheel_rf_link.STL" />
      </geometry>
      <material
        name="">
        <color
          rgba="0.752941176470588 0.752941176470588 0.752941176470588 1" />
      </material>
    </visual>
    <collision>
      <origin
        xyz="0 0 0"
        rpy="0 0 0" />
      <geometry>
        <mesh
          filename="package://robot_description5/meshes/Wheel_rf_link.STL" />
      </geometry>
    </collision>
  </link>
  <joint
    name="Wheel_rf_joint"
    type="continuous">
    <origin
      xyz="0.17 -0.31 0.0450000000000002"
      rpy="0 0 0" />
    <parent
      link="base_link" />
    <child
      link="Wheel_rf_link" />
    <axis
      xyz="0 -1 0" />
  </joint>
  <link
    name="Head_Link">
    <inertial>
      <origin
        xyz="2.79731433176084E-06 -5.80152703891224E-07 0.0078643650529755"
        rpy="0 0 0" />
      <mass
        value="0.0461197953885854" />
      <inertia
        ixx="0.0527239825675312"
        ixy="8.00596326764116E-06"
        ixz="-1.88257809366352E-06"
        iyy="0.0527609244034292"
        iyz="3.90439772496413E-07"
        izz="0.0641569669630147" />
    </inertial>
    <visual>
      <origin
        xyz="0 0 0"
        rpy="0 0 0" />
      <geometry>
        <mesh
          filename="package://robot_description5/meshes/Head_Link.STL" />
      </geometry>
      <material
        name="">
        <color
          rgba="1 1 1 1" />
      </material>
    </visual>
    <collision>
      <origin
        xyz="0 0 0"
        rpy="0 0 0" />
      <geometry>
        <mesh
          filename="package://robot_description5/meshes/Head_Link.STL" />
      </geometry>
    </collision>
  </link>
  <joint
    name="Head_Joint"
    type="fixed">
    <origin
      xyz="0 0 1.11745148448196"
      rpy="0 0 0" />
    <parent
      link="base_link" />
    <child
      link="Head_Link" />
    <axis
      xyz="0 0 1" />
  </joint>

    <link name="laser_link">
        <inertial>
            <mass value="0.001" />
            <origin xyz="0 0 0" />
            <inertia ixx="0.01" ixy="0.0" ixz="0.0"
                        iyy="0.01" iyz="0.0"
                        izz="0.01" />
        </inertial>

        <visual>
            <origin xyz=" 0 0 0 " rpy="0 0 0" />
            <geometry>
                <cylinder length="0.05" radius="0.05"/>
            </geometry>
            <material name="black"/>
        </visual>

        <collision>
            <origin xyz="0.0 0.0 0.0" rpy="0 0 0" />
            <geometry>
                <cylinder length="0.05" radius="0.05"/>
            </geometry>
        </collision>
    </link>
    <gazebo reference="laser_link">
        <material>Gazebo/Grey</material>
    </gazebo>

    <gazebo reference="laser_link">
        <sensor type="ray" name="rplidar">
            <pose>0 0 0 0 0 0</pose>
            <visualize>false</visualize>
            <update_rate>40</update_rate>
            <ray>
                <scan>
                    <horizontal>
                    <samples>360</samples>
                    <resolution>1</resolution>
                    <min_angle>-1.40</min_angle>
                    <max_angle>1.40</max_angle>
                    </horizontal>
                </scan>
                <range>
                    <min>0.10</min>
                    <max>30.0</max>
                    <resolution>0.01</resolution>
                </range>
                <noise>
                    <type>gaussian</type>
                    <mean>0.0</mean>
                    <stddev>0.01</stddev>
                </noise>
            </ray>
            <plugin name="gazebo_rplidar" filename="libgazebo_ros_laser.so">
                <topicName>/scan</topicName>
                <frameName>laser_link</frameName>
            </plugin>
        </sensor>
    </gazebo>

	<joint name="rplidar_joint" type="fixed">
		<origin xyz="0.27 0.0 0.20" rpy="0 0 0" />
		<parent link="base_link"/>
		<child link="laser_link"/>
	</joint>

  <gazebo>
    <plugin name="mbot_drive_controller" filename="libgazebo_ros_planar_move.so">
        <commandTopic>cmd_vel</commandTopic>
        <odometryTopic>odom</odometryTopic>
        <odometryFrame>odom</odometryFrame>
        <odometryRate>50</odometryRate>
        <robotBaseFrame>base_link</robotBaseFrame>
    </plugin>
  </gazebo>

</robot>